Certainly! Here's an explanation of `defer`, `panic`, and `recover`, along with examples for each:

1. `defer`:
- The `defer` statement is used to schedule a function call to be executed when the surrounding function completes, whether it returns normally or panics.
- Deferred functions are executed in a last-in-first-out (LIFO) order.
- It is commonly used for tasks like closing files, releasing resources, or logging.

Example:
```go
func main() {
	defer fmt.Println("World")
	fmt.Println("Hello")
}
```
Output:
```
Hello
World
```
Explanation:
- In this example, the `defer` statement is used to schedule the `fmt.Println("World")` function call to be executed after the surrounding function (`main`) completes.
- The `fmt.Println("Hello")` statement is executed first, followed by the deferred function call, which prints "World" to the console.
- The `defer` statement allows us to delay the execution of a function until the surrounding function finishes its execution.

2. `panic`:
- `panic` is a built-in function in Go that is used to interrupt the normal execution flow of a program and start panicking.
- When a function encounters a panic, it immediately stops execution and begins to unwind the stack, executing any deferred functions along the way.
- Panic is often used to handle exceptional or unrecoverable situations in the program.

Example:
```go
func main() {
	fmt.Println("Start")
	panic("Something went wrong!")
	fmt.Println("End")
}
```
Output:
```
Start
panic: Something went wrong!
```
Explanation:
- In this example, when the `panic` function is called with the message "Something went wrong!", it triggers a panic and interrupts the normal execution flow.
- The program stops executing immediately after the `panic` call, and the message "Something went wrong!" is printed to the console.
- The following `fmt.Println("End")` statement is not executed because it is never reached due to the panic.

3. `recover`:
- `recover` is a built-in function used to regain control of a panicking goroutine.
- It is only useful when called inside a deferred function.
- `recover` stops the panic and returns the value passed to the `panic` call.
- It allows us to gracefully handle panics and resume normal execution.

Example:
```go
func main() {
	defer func() {
		if err := recover(); err != nil {
			fmt.Println("Recovered:", err)
		}
	}()
	panic("Something went wrong!")
	fmt.Println("This line will not be executed")
}
```
Output:
```
Recovered: Something went wrong!
```
Explanation:
- In this example, the deferred function with `recover` is called when a panic occurs.
- Inside the deferred function, `recover` is used to recover from the panic and obtain the panic value ("Something went wrong!").
- The recovered value is then printed to the console, allowing the program to continue executing after the panic.
- The line `fmt.Println("This line will not be executed")` is not executed because it comes after the panic and is never reached.

Note: It's important to use `panic` and `recover` judiciously. Panics should be reserved for exceptional situations where normal execution cannot proceed, and recover should be used to gracefully handle those situations and allow the program to continue execution whenever possible.